2020-05-08 18:55:53,415:__main__:cargar_marcas_csv:Error For: tuple indices must be integers or slices, not str
Traceback (most recent call last):
  File "/home/gerardo/PycharmProjects/combobox/combov2.py", line 78, in cargar_marcas_csv
    data[row["Marca"]].append(row["Modelo"])
TypeError: tuple indices must be integers or slices, not str
2020-05-08 18:57:31,978:__main__:cargar_marcas_csv:Error For: tuple indices must be integers or slices, not str
Traceback (most recent call last):
  File "/home/gerardo/PycharmProjects/combobox/combov2.py", line 77, in cargar_marcas_csv
    data[row["Marca"]].append(row["Modelo"])
TypeError: tuple indices must be integers or slices, not str
2020-05-08 18:59:21,520:__main__:cargar_marcas_csv:Error For: tuple indices must be integers or slices, not str
Traceback (most recent call last):
  File "/home/gerardo/PycharmProjects/combobox/combov2.py", line 77, in cargar_marcas_csv
    data[row["Marca"]].append(row["Modelo"])
TypeError: tuple indices must be integers or slices, not str
2020-05-08 19:38:02,322:__main__:cargar_marcas:Error For: tuple indices must be integers or slices, not tuple
Traceback (most recent call last):
  File "/home/gerardo/PycharmProjects/combobox/combov4.py", line 56, in cargar_marcas
    data[row[1,2]].append(row[3])
TypeError: tuple indices must be integers or slices, not tuple
2020-05-08 19:39:19,433:__main__:cargar_marcas:Error For: append() takes exactly one argument (2 given)
Traceback (most recent call last):
  File "/home/gerardo/PycharmProjects/combobox/combov4.py", line 56, in cargar_marcas
    data[row[1], row[0]].append(row[3],row[2])
TypeError: append() takes exactly one argument (2 given)
2020-05-08 19:42:29,687:__main__:cargar_marcas:Error For: too many values to unpack (expected 2)
Traceback (most recent call last):
  File "/home/gerardo/PycharmProjects/combobox/combov4.py", line 55, in cargar_marcas
    for row, row1 in reader:
ValueError: too many values to unpack (expected 2)
2020-05-08 19:43:09,389:__main__:cargar_marcas:Error For: too many values to unpack (expected 2)
Traceback (most recent call last):
  File "/home/gerardo/PycharmProjects/combobox/combov4.py", line 55, in cargar_marcas
    for row, row1 in reader:
ValueError: too many values to unpack (expected 2)
2020-05-08 19:43:25,529:__main__:cargar_marcas:Error For: too many values to unpack (expected 2)
Traceback (most recent call last):
  File "/home/gerardo/PycharmProjects/combobox/combov4.py", line 55, in cargar_marcas
    for row, row1 in reader:
ValueError: too many values to unpack (expected 2)
2020-05-08 19:50:42,730:__main__:cargar_marcas:Error For: too many values to unpack (expected 2)
Traceback (most recent call last):
  File "/home/gerardo/PycharmProjects/combobox/combov4.py", line 58, in cargar_marcas
    for row, v in reader:
ValueError: too many values to unpack (expected 2)
2020-05-08 19:51:29,064:__main__:cargar_marcas:Error For: too many values to unpack (expected 2)
Traceback (most recent call last):
  File "/home/gerardo/PycharmProjects/combobox/combov4.py", line 58, in cargar_marcas
    for row, v in reader:
ValueError: too many values to unpack (expected 2)
2020-05-08 20:00:08,115:__main__:cargar_marcas:Error For: tuple indices must be integers or slices, not tuple
Traceback (most recent call last):
  File "/home/gerardo/PycharmProjects/combobox/combov4.py", line 58, in cargar_marcas
    data[row[0,1]].append(row[3])
TypeError: tuple indices must be integers or slices, not tuple
2020-05-08 20:11:13,681:__main__:cargar_marcas:Error For: append() takes exactly one argument (2 given)
Traceback (most recent call last):
  File "/home/gerardo/PycharmProjects/combobox/combov4.py", line 58, in cargar_marcas
    data[row[0],row[1]].append(row[3], row[2])
TypeError: append() takes exactly one argument (2 given)
2020-05-08 20:12:05,219:__main__:cargar_marcas:Error For: 'int' object has no attribute 'append'
Traceback (most recent call last):
  File "/home/gerardo/PycharmProjects/combobox/combov4.py", line 58, in cargar_marcas
    data[row[0],row[1]].append(row[3])
AttributeError: 'int' object has no attribute 'append'
2020-05-24 19:00:14,694:__main__:cargar_marcas:Error DB: 2003: Can't connect to MySQL server on 'localhost:3306' (111 Connection refused)
Traceback (most recent call last):
  File "/home/gerardo/PycharmProjects/combobox/venv/lib/python3.7/site-packages/mysql/connector/network.py", line 509, in open_connection
    self.sock.connect(sockaddr)
ConnectionRefusedError: [Errno 111] Connection refused

During handling of the above exception, another exception occurred:

Traceback (most recent call last):
  File "/home/gerardo/PycharmProjects/combobox/combov3.py", line 47, in cargar_marcas
    conn = MySQLConnection(**dbconfig)
  File "/home/gerardo/PycharmProjects/combobox/venv/lib/python3.7/site-packages/mysql/connector/connection.py", line 95, in __init__
    self.connect(**kwargs)
  File "/home/gerardo/PycharmProjects/combobox/venv/lib/python3.7/site-packages/mysql/connector/abstracts.py", line 716, in connect
    self._open_connection()
  File "/home/gerardo/PycharmProjects/combobox/venv/lib/python3.7/site-packages/mysql/connector/connection.py", line 206, in _open_connection
    self._socket.open_connection()
  File "/home/gerardo/PycharmProjects/combobox/venv/lib/python3.7/site-packages/mysql/connector/network.py", line 512, in open_connection
    errno=2003, values=(self.get_address(), _strioerror(err)))
mysql.connector.errors.InterfaceError: 2003: Can't connect to MySQL server on 'localhost:3306' (111 Connection refused)
